Workbook

Sheet Planilha de Compra
A1: ToolKey | B1: Categoria | C1: Ferramenta | D1: Prioridade | E1: Dono | F1: Quando contratar | G1: Roda onde | H1: Acessa HubSpot? (como) | I1: Unifica info (como) | J1: Modelo de cobrança | K1: Custo mensal modelado (USD) | L1: Custos ocultos / pegadinhas | M1: Limites no Orquestrador (anti-custo) | N1: Fonte/Preço/Doc URL
A2: lovable_provider_assistido | B2: Orquestração | C2: Lovable (provider assistido) | D2: P1 | E2: Produto/Operação | F2: Fase 0-1 | G2: SaaS (Lovable) + GitHub Sync | H2: Não acessa HubSpot; gera app a partir de blueprint/design | I2: Exporta repo/ZIP -> GitHub -> CI | J2: Créditos/mês | K2: =IFERROR(VLOOKUP(A2,Assumptions_Custos!$A$65:$B$92,2,FALSE),0) | L2: Consumo de créditos em iterações; lock-in em secrets/auth se ficar no Lovable Cloud | M2: Limite de execuções/branch por dia; exigir export GitHub sempre | N2: https://docs.lovable.dev/introduction/plans-and-credits
A3: supabase_postgres_auth_storage_edge | B3: Backend/Fonte da Verdade | C3: Supabase (Postgres/Auth/Storage/Edge) | D3: P0 | E3: Backend/Infra | F3: Fase 0 | G3: Cloud (Supabase) ou self-host | H3: Via API oficial/export; não via senha | I3: DB central + storage + RLS multi-tenant | J3: Plano + compute + overage | K3: =IFERROR(VLOOKUP(A3,Assumptions_Custos!$A$65:$B$92,2,FALSE),0) | L3: Compute escala por projeto; overage de MAU/egress; add-ons (PITR, replicas) fora do spend-cap | M3: Spend cap ON; quotas por tenant; rate-limit Edge Functions | N3: https://supabase.com/docs/guides/platform/billing-on-supabase
A4: temporal_cloud_state_machine_de_runs | B4: Orquestração | C4: Temporal Cloud (state machine de runs) | D4: P0 | E4: Infra/Backend | F4: Fase 0 | G4: Cloud (AWS marketplace) ou self-host | H4: Não acessa HubSpot | I4: Workflow engine: estados, retries, idempotência | J4: Fee + $/ação | K4: =IFERROR(VLOOKUP(A4,Assumptions_Custos!$A$65:$B$92,2,FALSE),0) | L4: Ações explodem com retries mal configurados; necessidade de métricas/alertas | M4: Cap de ações/run; backoff; dead-letter; limites de concorrência | N4: https://temporal.io/get-cloud/aws-marketplace
A5: upstash_redis | B5: Fila/Jobs | C5: Upstash Redis | D5: P1 | E5: Infra | F5: Fase 0 | G5: Cloud | H5: Não acessa HubSpot | I5: Cache/locks/rate-limit; filas simples | J5: Uso + plano | K5: =IFERROR(VLOOKUP(A5,Assumptions_Custos!$A$65:$B$92,2,FALSE),0) | L5: Prod Pack caro por DB; custos por multi-região | M5: Rate-limit global; TTL obrigatório; quotas por tenant | N5: https://upstash.com/pricing
A6: upstash_qstash_webhooks_retries | B6: Fila/Jobs | C6: Upstash QStash (webhooks/retries) | D6: P1 | E6: Infra | F6: Fase 0 | G6: Cloud | H6: Não acessa HubSpot | I6: Entrega eventos + retries; schedules | J6: $ por mensagens | K6: =IFERROR(VLOOKUP(A6,Assumptions_Custos!$A$65:$B$92,2,FALSE),0) | L6: Retries contam; custos por burst; Prod Pack +$200 | M6: Cap msgs/dia; DLQ curto; max retry count | N6: https://upstash.com/pricing/qstash
A7: cloudflare_workers_opcional | B7: Edge/Workers | C7: Cloudflare Workers (opcional) | D7: P2 | E7: Infra | F7: Fase 2 | G7: Edge | H7: Não acessa HubSpot | I7: Webhooks/edge proxy/roteamento | J7: $5 base + uso | K7: =IFERROR(VLOOKUP(A7,Assumptions_Custos!$A$65:$B$92,2,FALSE),0) | L7: CPU ms pode subir com LLM/chamadas pesadas | M7: Cap requests/mês; cap CPUms; alertas | N7: https://developers.cloudflare.com/workers/platform/pricing/
A8: flow_recorder | B8: CAPTURE UI | C8: Flow Recorder | D8: P0 | E8: QA/Produto | F8: Fase 1 (captura) | G8: Extensão browser | H8: Usa sessão já logada (não pega senha) | I8: Exporta sessões/fluxos p/ repositório | J8: Assinatura (mensal) | K8: =IFERROR(VLOOKUP(A8,Assumptions_Custos!$A$65:$B$92,2,FALSE),0) | L8: Limites de sessões/playbacks no plano; precisa padronizar naming/escopo | M8: Limitar captura por fluxo; checklist de cobertura | N8: https://flowrecorder.com/pricing
A9: playwright | B9: CAPTURE UI | C9: Playwright | D9: P0 | E9: QA/Eng | F9: Fase 1-2 | G9: CI + local | H9: Pode usar login automatizado ou storageState; não 'quebra' senha | I9: Scripts versionados no Git | J9: Open source | K9: =IFERROR(VLOOKUP(A9,Assumptions_Custos!$A$65:$B$92,2,FALSE),0) | L9: Manutenção de seletores; flakiness; custo de infra CI | M9: Retry controlado; video/trace só em falha | N9: https://playwright.dev/
A10: chrome_devtools_recorder | B10: CAPTURE UI | C10: Chrome DevTools Recorder | D10: P1 | E10: QA | F10: Fase 1 | G10: Chrome local | H10: Sessão logada | I10: Export JSON -> Playwright/Puppeteer | J10: Gratuito | K10: =IFERROR(VLOOKUP(A10,Assumptions_Custos!$A$65:$B$92,2,FALSE),0) | L10: Baixa escalabilidade; gravações 'cruas' | M10: Uso só para seed; converter p/ Playwright | N10: https://developer.chrome.com/docs/devtools/recorder/
A11: mitmproxy | B11: CAPTURE HAR/HTTP | C11: mitmproxy | D11: P0 | E11: Eng/QA | F11: Fase 1 | G11: PC técnico/CI | H11: Captura tráfego do navegador logado; não autentica sozinho | I11: HAR/flows por fluxo -> storage | J11: Open source | K11: =IFERROR(VLOOKUP(A11,Assumptions_Custos!$A$65:$B$92,2,FALSE),0) | L11: HTTPS intercept exige certificado; risco operacional se usar errado | M11: Capturar só domínios allowlist; mascarar PII | N11: https://mitmproxy.org/
A12: fiddler_everywhere | B12: CAPTURE HAR/HTTP | C12: Fiddler Everywhere | D12: P1 | E12: Eng/QA | F12: Fase 1 | G12: PC técnico | H12: Captura tráfego do browser logado; não pega senha | I12: Export SAZ/HAR | J12: Por usuário | K12: =IFERROR(VLOOKUP(A12,Assumptions_Custos!$A$65:$B$92,2,FALSE),0) | L12: Enterprise para captura em máquinas de usuários finais; política/SSO | M12: Uso só por máquina 'captura'; não em todo PC | N12: https://www.telerik.com/purchase/fiddler
A13: hubspot_apis_oficial_exports | B13: EXTRACT CONFIG | C13: HubSpot APIs (oficial) + Exports | D13: P0 | E13: Eng/Data | F13: Fase 1 | G13: Server/CI | H13: OAuth/token oficial | I13: Dump de objetos/pipelines/propriedades/RBAC (o que for exposto) | J13: Depende do plano HubSpot | K13: =IFERROR(VLOOKUP(A13,Assumptions_Custos!$A$65:$B$92,2,FALSE),0) | L13: Limitações ToS/escopo; rate limits; nem tudo é exposto | M13: Backoff e cache; jobs incrementais; audit log | N13: https://developers.hubspot.com/
... A47: axe_core_a11y | B47: Acessibilidade | C47: axe-core (a11y) | D47: P2 | E47: QA/Design | F47: Fase 4 | G47: CI | H47: Não | I47: Gate a11y | J47: Open source | K47: =IFERROR(VLOOKUP(A47,Assumptions_Custos!$A$65:$B$92,2,FALSE),0) | L47: Regra por produto; tuning | M47: Fail só em severidade alta no começo | N47: https://github.com/dequelabs/axe-core

Sheet Assumptions_Custos
A1: Assumptions (edite só as células amarelas)
A2: Chave | B2: Valor | C2: Descrição | D2: Observação
A4: TEAM_SEATS_GITHUB | B4: 8 | C4: Assentos GitHub Team
A5: ACTIONS_MINUTES_MONTH | B5: 20000 | C5: Minutos Actions/mês (após franquia)
A6: ACTIONS_RATE_PER_MIN | B6: 0.008 | C6: USD/min (runner Linux típico)
A7: ACTIVE_COMMITTERS_SECURITY | B7: 6 | C7: Committers ativos (GitHub Secret/Code Security)
A8: FLOWRECORDER_PLAN_USD | B8: 49.99 | C8: Flow Recorder plano (ex.: Pro)
A9: FIDDLER_USERS | B9: 2 | C9: Usuários Fiddler
A10: FIDDLER_USD_PER_USER | B10: 18 | C10: USD/usuário/mês (mensal)
A11: POSTMAN_USERS | B11: 3 | C11: Usuários Postman
A12: POSTMAN_USD_PER_USER | B12: 29 | C12: USD/usuário/mês (Pro)
A13: STOPLIGHT_PLAN_BASE | B13: 147 | C13: Stoplight Startup (mensal) ou equivalente
A14: STOPLIGHT_INCLUDED_USERS | B14: 8 | C14: Stoplight usuários incluídos
A15: STOPLIGHT_EXTRA_USERS | B15: 0 | C15: Stoplight usuários extras
... A59: SEMGREP_USD_PER_CONTRIB | B59: 40 | C59: USD/contributor/mês (Teams)
A63: Costs
A64: ToolKey | B64: MonthlyUSD | C64: Como calcula (resumo)
A65: github_team | B65: =$B$4*4 | C65: Team $4/user/mo (promo first 12 mo)
A66: github_actions_minutos | B66: =$B$5*$B$6 | C66: Minutes * rate (set your real runner rate)
A67: flow_recorder | B67: =$B$8 | C67: Plano escolhido
A68: fiddler_everywhere | B68: =$B$9*$B$10 | C68: Usuários * preço
A69: postman_colecoes_schema | B69: =$B$11*$B$12 | C69: Usuários * preço
A70: stoplight_openapi_contract_first | B70: =$B$13+$B$15*$B$16 | C70: Plano base + extras
A71: supabase_postgres_auth_storage_edge | B71: =$B$17+$B$18*$B$19+$B$20 | C71: Fee + compute/projeto + buffer
A72: temporal_cloud_state_machine_de_runs | B72: =$B$21+($B$22/1000000)*$B$23 | C72: Plan fee + actions
A73: upstash_redis | B73: =$B$24+$B$25 | C73: Fixed + ProdPack
A74: upstash_qstash_webhooks_retries | B74: =$B$28+($B$26/100000)*$B$27 | C74: Fixed + msgs usage
A75: cloudflare_workers_opcional | B75: =$B$29+MAX(0,($B$30-10))*$B$31 | C75: Base + overage (>10M incl.)
A76: chromatic_storybook_visual_diff | B76: =$B$32+$B$33*$B$34 | C76: Plano + overage snapshots
A77: applitools_visual_ai | B77: =$B$35 | C77: Média mensal (contrato anual)
A78: sentry | B78: =$B$36 | C78: Base (overage não incluso)
A79: datadog_infra_apm | B79: =$B$37*$B$38 | C79: Hosts * rate (infra)
A80: 1password_business_secrets_manager | B80: =$B$39*$B$40 | C80: Users * rate (anual)
A81: figma | B81: =$B$41*$B$42 | C81: Full seats * rate
A82: locofy_figma_react | B82: =$B$43 | C82: Média mensal (anual)
A83: github_copilot_business | B83: =$B$44*$B$45 | C83: Seats * rate
A84: cursor_teams_opcional | B84: =$B$46*$B$47 | C84: Seats * rate
A85: openai_api_byok | B85: =$B$48*$B$50+$B$49*$B$51 | C85: Tokens input+output
A86: anthropic_claude_api_byok | B86: =$B$52*$B$54+$B$53*$B$55 | C86: Tokens input+output
A87: apify_scraping_de_docs_ui_publica | B87: =$B$56+$B$57 | C87: Plano base + extra
...

Sheet Resumo
A1: Resumo de custos (modelado)
A3: Total mensal estimado (USD) | B3: =SUM('Planilha de Compra'!$K$2:$K$47)
A5: Categoria | B5: Custo mensal (USD)
A6: AI Dev | B6: =SUMIF('Planilha de Compra'!$B$2:$B$47,A6,'Planilha de Compra'!$K$2:$K$47)
A7: Acessibilidade | B7: =SUMIF('Planilha de Compra'!$B$2:$B$47,A7,'Planilha de Compra'!$K$2:$K$47)
A8: Backend/Fonte da Verdade | B8: =SUMIF('Planilha de Compra'!$B$2:$B$47,A8,'Planilha de Compra'!$K$2:$K$47)
A9: CAPTURE HAR/HTTP | B9: =SUMIF('Planilha de Compra'!$B$2:$B$47,A9,'Planilha de Compra'!$K$2:$K$47)
A10: CAPTURE UI | B10: =SUMIF('Planilha de Compra'!$B$2:$B$47,A10,'Planilha de Compra'!$K$2:$K$47)
A11: CI/CD | B11: =SUMIF('Planilha de Compra'!$B$2:$B$47,A11,'Planilha de Compra'!$K$2:$K$47)
A12: Contrato API | B12: =SUMIF('Planilha de Compra'!$B$2:$B$47,A12,'Planilha de Compra'!$K$2:$K$47)
A13: Design | B13: =SUMIF('Planilha de Compra'!$B$2:$B$47,A13,'Planilha de Compra'!$K$2:$K$47)
A14: Design→Código | B14: =SUMIF('Planilha de Compra'!$B$2:$B$47,A14,'Planilha de Compra'!$K$2:$K$47)
A15: EXTRACT CONFIG | B15: =SUMIF('Planilha de Compra'!$B$2:$B$47,A15,'Planilha de Compra'!$K$2:$K$47)
A16: Edge/Workers | B16: =SUMIF('Planilha de Compra'!$B$2:$B$47,A16,'Planilha de Compra'!$K$2:$K$47)
A17: Fila/Jobs | B17: =SUMIF('Planilha de Compra'!$B$2:$B$47,A17,'Planilha de Compra'!$K$2:$K$47)
... A31: State Machines UI | B31: =SUMIF('Planilha de Compra'!$B$2:$B$47,A31,'Planilha de Compra'!$K$2:$K$47)
A34: Observação
A35: Edite o sheet Assumptions_Custos (células amarelas) para refletir seu time/uso real. Total é uma estimativa.
